Workbook

Sheet Raw
A1: txn_id | B1: device_id | C1: txn_time | D1: txn_type | E1: amount | F1: status | G1: error_code | H1: model (ВПР) | I1: location (ВПР) | J1: is_success | K1: service_cost (ВПР) | N1: device_id | O1: location | P1: model | Q1: last_online | R1: status | S1: cash_level
A2: T000001 | B2: ATM-001 | C2: 46266.158 | D2: снятие | E2: 15000 | F2: success | H2: =VLOOKUP(B2,$N$2:$S$41,3,FALSE()) -> Model-X | I2: =VLOOKUP(B2,$N$2:$S$41,2,FALSE()) -> Москва, Тверская | J2: =IF(F2="success",1,0) -> 1 | K2: =VLOOKUP(H2,Lookup!$A$4:$B$6,2,FALSE()) -> 18 | N2: ATM-001 | O2: Москва, Тверская | P2: Model-X | Q2: 46295.919 | R2: online | S2: 31
A3: T000002 | B3: ATM-036 | C3: 46266.317 | D3: снятие | E3: 15000 | F3: success | H3: =VLOOKUP(B3,$N$2:$S$41,3,FALSE()) -> Model-X | I3: =VLOOKUP(B3,$N$2:$S$41,2,FALSE()) -> Воронеж, Кольцовская | J3: =IF(F3="success",1,0) -> 1 | K3: =VLOOKUP(H3,Lookup!$A$4:$B$6,2,FALSE()) -> 18 | N3: ATM-002 | O3: Москва, Арбат | P3: Model-Y | Q3: 46295.803 | R3: online | S3: 59
A4: T000003 | B4: ATM-022 | C4: 46266.381 | D4: запрос баланса | E4: 0 | F4: success | H4: =VLOOKUP(B4,$N$2:$S$41,3,FALSE()) -> Model-X | I4: =VLOOKUP(B4,$N$2:$S$41,2,FALSE()) -> Новосибирск, Дуси Ковальчук | J4: =IF(F4="success",1,0) -> 1 | K4: =VLOOKUP(H4,Lookup!$A$4:$B$6,2,FALSE()) -> 18 | N4: ATM-003 | O4: Москва, Новослободская | P4: Model-Z | Q4: 46295.84 | R4: online | S4: 12
A5: T000004 | B5: ATM-006 | C5: 46266.385 | D5: запрос баланса | E5: 0 | F5: success | H5: =VLOOKUP(B5,$N$2:$S$41,3,FALSE()) -> Model-X | I5: =VLOOKUP(B5,$N$2:$S$41,2,FALSE()) -> Москва, Профсоюзная | J5: =IF(F5="success",1,0) -> 1 | K5: =VLOOKUP(H5,Lookup!$A$4:$B$6,2,FALSE()) -> 18 | N5: ATM-004 | O5: Москва, Ленинградский пр-т | P5: Model-X | Q5: 46295.926 | R5: online | S5: 39
A6: T000005 | B6: ATM-012 | C6: 46266.39 | D6: снятие | E6: 1000 | F6: success | H6: =VLOOKUP(B6,$N$2:$S$41,3,FALSE()) -> Model-Z | I6: =VLOOKUP(B6,$N$2:$S$41,2,FALSE()) -> Казань, Кремлёвская | J6: =IF(F6="success",1,0) -> 1 | K6: =VLOOKUP(H6,Lookup!$A$4:$B$6,2,FALSE()) -> 16 | N6: ATM-005 | O6: Москва, Кутузовский пр-т | P6: Model-Y | Q6: 46295.699 | R6: online | S6: 32
A7: T000006 | B7: ATM-034 | C7: 46266.463 | D7: запрос баланса | E7: 0 | F7: success | H7: =VLOOKUP(B7,$N$2:$S$41,3,FALSE()) -> Model-X | I7: =VLOOKUP(B7,$N$2:$S$41,2,FALSE()) -> Краснодар, Гимназическая | J7: =IF(F7="success",1,0) -> 1 | K7: =VLOOKUP(H7,Lookup!$A$4:$B$6,2,FALSE()) -> 18 | N7: ATM-006 | O7: Москва, Профсоюзная | P7: Model-X | Q7: 46295.978 | R7: online | S7: 39
A8: T000007 | B8: ATM-035 | C8: 46266.478 | D8: внесение | E8: 7000 | F8: success | H8: =VLOOKUP(B8,$N$2:$S$41,3,FALSE()) -> Model-Y | I8: =VLOOKUP(B8,$N$2:$S$41,2,FALSE()) -> Воронеж, Плехановская | J8: =IF(F8="success",1,0) -> 1 | K8: =VLOOKUP(H8,Lookup!$A$4:$B$6,2,FALSE()) -> 14 | N8: ATM-007 | O8: Санкт-Петербург, Невский пр-т | P8: Model-X | Q8: 46289.486 | R8: online | S8: 55
A9: T000008 | B9: ATM-036 | C9: 46266.48 | D9: снятие | E9: 2000 | F9: success | H9: =VLOOKUP(B9,$N$2:$S$41,3,FALSE()) -> Model-X | I9: =VLOOKUP(B9,$N$2:$S$41,2,FALSE()) -> Воронеж, Кольцовская | J9: =IF(F9="success",1,0) -> 1 | K9: =VLOOKUP(H9,Lookup!$A$4:$B$6,2,FALSE()) -> 18 | N9: ATM-008 | O9: Санкт-Петербург, Московский пр-т | P9: Model-Y | Q9: 46295.833 | R9: online | S9: 92
A10: T000009 | B10: ATM-030 | C10: 46266.543 | D10: снятие | E10: 1000 | F10: success | H10: =VLOOKUP(B10,$N$2:$S$41,3,FALSE()) -> Model-Z | I10: =VLOOKUP(B10,$N$2:$S$41,2,FALSE()) -> Ростов-на-Дону, Будённовский | J10: =IF(F10="success",1,0) -> 1 | K10: =VLOOKUP(H10,Lookup!$A$4:$B$6,2,FALSE()) -> 16 | N10: ATM-009 | O10: Санкт-Петербург, Лиговский пр-т | P10: Model-Z | Q10: 46283.132 | R10: offline | S10: 31
A11: T000010 | B11: ATM-032 | C11: 46266.569 | D11: запрос баланса | E11: 0 | F11: success | H11: =VLOOKUP(B11,$N$2:$S$41,3,FALSE()) -> Model-Y | I11: =VLOOKUP(B11,$N$2:$S$41,2,FALSE()) -> Краснодар, Красная | J11: =IF(F11="success",1,0) -> 1 | K11: =VLOOKUP(H11,Lookup!$A$4:$B$6,2,FALSE()) -> 14 | N11: ATM-010 | O11: Санкт-Петербург, Большой пр-т | P11: Model-X | Q11: 46295.6 | R11: online | S11: 53
A12: T000011 | B12: ATM-030 | C12: 46266.594 | D12: запрос баланса | E12: 0 | F12: success | H12: =VLOOKUP(B12,$N$2:$S$41,3,FALSE()) -> Model-Z | I12: =VLOOKUP(B12,$N$2:$S$41,2,FALSE()) -> Ростов-на-Дону, Будённовский | J12: =IF(F12="success",1,0) -> 1 | K12: =VLOOKUP(H12,Lookup!$A$4:$B$6,2,FALSE()) -> 16 | N12: ATM-011 | O12: Казань, Баумана | P12: Model-X | Q12: 46295.611 | R12: online | S12: 81
A13: T000012 | B13: ATM-007 | C13: 46266.612 | D13: перевод | E13: 10000 | F13: success | H13: =VLOOKUP(B13,$N$2:$S$41,3,FALSE()) -> Model-X | I13: =VLOOKUP(B13,$N$2:$S$41,2,FALSE()) -> Санкт-Петербург, Невский пр-т | J13: =IF(F13="success",1,0) -> 1 | K13: =VLOOKUP(H13,Lookup!$A$4:$B$6,2,FALSE()) -> 18 | N13: ATM-012 | O13: Казань, Кремлёвская | P13: Model-Z | Q13: 46294.639 | R13: maintenance | S13: 56
... A15: T000014 | B15: ATM-029 | C15: 46266.775 | D15: снятие | E15: 1500 | F15: success | H15: =VLOOKUP(B15,$N$2:$S$41,3,FALSE()) -> Model-Y | I15: =VLOOKUP(B15,$N$2:$S$41,2,FALSE()) -> Ростов-на-Дону, Садовая | J15: =IF(F15="success",1,0) -> 1 | K15: =VLOOKUP(H15,Lookup!$A$4:$B$6,2,FALSE()) -> 14 | N15: ATM-014 | O15: Казань, Чистопольская | P15: Model-Y | Q15: 46290.67 | R15: online | S15: 28
A16: T000015 | B16: ATM-004 | C16: 46266.812 | D16: снятие | E16: 10000 | F16: failed | G16: E01 | H16: =VLOOKUP(B16,$N$2:$S$41,3,FALSE()) -> Model-X | I16: =VLOOKUP(B16,$N$2:$S$41,2,FALSE()) -> Москва, Ленинградский пр-т | J16: =IF(F16="success",1,0) -> 0 | K16: =VLOOKUP(H16,Lookup!$A$4:$B$6,2,FALSE()) -> 18 | N16: ATM-015 | O16: Екатеринбург, Ленина | P16: Model-Z | Q16: 46295.885 | R16: online | S16: 82
A17: T000016 | B17: ATM-034 | C17: 46266.816 | D17: перевод | E17: 2000 | F17: success | H17: =VLOOKUP(B17,$N$2:$S$41,3,FALSE()) -> Model-X | I17: =VLOOKUP(B17,$N$2:$S$41,2,FALSE()) -> Краснодар, Гимназическая | J17: =IF(F17="success",1,0) -> 1 | K17: =VLOOKUP(H17,Lookup!$A$4:$B$6,2,FALSE()) -> 18 | N17: ATM-016 | O17: Екатеринбург, Малышева | P17: Model-X | Q17: 46295.757 | R17: online | S17: 63
A18: T000017 | B18: ATM-019 | C18: 46266.826 | D18: внесение | E18: 1500 | F18: success | H18: =VLOOKUP(B18,$N$2:$S$41,3,FALSE()) -> Model-X | I18: =VLOOKUP(B18,$N$2:$S$41,2,FALSE()) -> Новосибирск, Красный пр-т | J18: =IF(F18="success",1,0) -> 1 | K18: =VLOOKUP(H18,Lookup!$A$4:$B$6,2,FALSE()) -> 18 | N18: ATM-017 | O18: Екатеринбург, 8 Марта | P18: Model-Y | Q18: 46286.938 | R18: offline | S18: 47
A19: T000018 | B19: ATM-010 | C19: 46266.841 | D19: снятие | E19: 1000 | F19: success | H19: =VLOOKUP(B19,$N$2:$S$41,3,FALSE()) -> Model-X | I19: =VLOOKUP(B19,$N$2:$S$41,2,FALSE()) -> Санкт-Петербург, Большой пр-т | J19: =IF(F19="success",1,0) -> 1 | K19: =VLOOKUP(H19,Lookup!$A$4:$B$6,2,FALSE()) -> 18 | N19: ATM-018 | O19: Екатеринбург, Вайнера | P19: Model-Z | Q19: 46295.846 | R19: online | S19: 71
A20: T000019 | B20: ATM-017 | C20: 46267.353 | D20: запрос баланса | E20: 0 | F20: success | H20: =VLOOKUP(B20,$N$2:$S$41,3,FALSE()) -> Model-Y | I20: =VLOOKUP(B20,$N$2:$S$41,2,FALSE()) -> Екатеринбург, 8 Марта | J20: =IF(F20="success",1,0) -> 1 | K20: =VLOOKUP(H20,Lookup!$A$4:$B$6,2,FALSE()) -> 14 | N20: ATM-019 | O20: Новосибирск, Красный пр-т | P20: Model-X | Q20: 46295.926 | R20: online | S20: 17
A21: T000020 | B21: ATM-017 | C21: 46267.607 | D21: снятие | E21: 2000 | F21: success | H21: =VLOOKUP(B21,$N$2:$S$41,3,FALSE()) -> Model-Y | I21: =VLOOKUP(B21,$N$2:$S$41,2,FALSE()) -> Екатеринбург, 8 Марта | J21: =IF(F21="success",1,0) -> 1 | K21: =VLOOKUP(H21,Lookup!$A$4:$B$6,2,FALSE()) -> 14 | N21: ATM-020 | O21: Новосибирск, Ленина | P21: Model-Y | Q21: 46295.728 | R21: online | S21: 40
A22: T000021 | B22: ATM-025 | C22: 46267.612 | D22: снятие | E22: 1500 | F22: success | H22: =VLOOKUP(B22,$N$2:$S$41,3,FALSE()) -> Model-X | I22: =VLOOKUP(B22,$N$2:$S$41,2,FALSE()) -> Нижний Новгород, Белинского | J22: =IF(F22="success",1,0) -> 1 | K22: =VLOOKUP(H22,Lookup!$A$4:$B$6,2,FALSE()) -> 18 | N22: ATM-021 | O22: Новосибирск, Гоголя | P22: Model-X | Q22: 46295.744 | R22: online
A23: T000022 | B23: ATM-007 | C23: 46267.64 | D23: снятие | E23: 5000 | F23: timeout | H23: =VLOOKUP(B23,$N$2:$S$41,3,FALSE()) -> Model-X | I23: =VLOOKUP(B23,$N$2:$S$41,2,FALSE()) -> Санкт-Петербург, Невский пр-т | J23: =IF(F23="success",1,0) -> 0 | K23: =VLOOKUP(H23,Lookup!$A$4:$B$6,2,FALSE()) -> 18 | N23: ATM-022 | O23: Новосибирск, Дуси Ковальчук | P23: Model-X | Q23: 46291.385 | R23: online | S23: 61
A24: T000023 | B24: ATM-016 | C24: 46267.764 | D24: внесение | E24: 2000 | F24: success | H24: =VLOOKUP(B24,$N$2:$S$41,3,FALSE()) -> Model-X | I24: =VLOOKUP(B24,$N$2:$S$41,2,FALSE()) -> Екатеринбург, Малышева | J24: =IF(F24="success",1,0) -> 1 | K24: =VLOOKUP(H24,Lookup!$A$4:$B$6,2,FALSE()) -> 18 | N24: ATM-023 | O24: Нижний Новгород, Большая Покровская | P24: Model-Y | Q24: 46295.968 | R24: online | S24: 86
A25: T000024 | B25: ATM-008 | C25: 46267.785 | D25: запрос баланса | E25: 0 | F25: success | H25: =VLOOKUP(B25,$N$2:$S$41,3,FALSE()) -> Model-Y | I25: =VLOOKUP(B25,$N$2:$S$41,2,FALSE()) -> Санкт-Петербург, Московский пр-т | J25: =IF(F25="success",1,0) -> 1 | K25: =VLOOKUP(H25,Lookup!$A$4:$B$6,2,FALSE()) -> 14 | N25: ATM-024 | O25: Нижний Новгород, Рождественская | P25: Model-Z | Q25: 46295.617 | R25: online | S25: 43
A26: T000025 | B26: ATM-021 | C26: 46267.789 | D26: внесение | E26: 5000 | F26: timeout | H26: =VLOOKUP(B26,$N$2:$S$41,3,FALSE()) -> Model-X | I26: =VLOOKUP(B26,$N$2:$S$41,2,FALSE()) -> Новосибирск, Гоголя | J26: =IF(F26="success",1,0) -> 0 | K26: =VLOOKUP(H26,Lookup!$A$4:$B$6,2,FALSE()) -> 18 | N26: ATM-025 | O26: Нижний Новгород, Белинского | P26: Model-X | Q26: 46295.73 | R26: online | S26: 38
A27: T000026 | B27: ATM-004 | C27: 46267.84 | D27: снятие | E27: 1000 | F27: success | H27: =VLOOKUP(B27,$N$2:$S$41,3,FALSE()) -> Model-X | I27: =VLOOKUP(B27,$N$2:$S$41,2,FALSE()) -> Москва, Ленинградский пр-т | J27: =IF(F27="success",1,0) -> 1 | K27: =VLOOKUP(H27,Lookup!$A$4:$B$6,2,FALSE()) -> 18 | N27: ATM-026 | O27: Самара, Ленинградская | P27: Model-X | Q27: 46277.583 | R27: offline | S27: 65
A28: T000027 | B28: ATM-023 | C28: 46267.846 | D28: перевод | E28: 2000 | F28: success | H28: =VLOOKUP(B28,$N$2:$S$41,3,FALSE()) -> Model-Y | I28: =VLOOKUP(B28,$N$2:$S$41,2,FALSE()) -> Нижний Новгород, Большая Покровская | J28: =IF(F28="success",1,0) -> 1 | K28: =VLOOKUP(H28,Lookup!$A$4:$B$6,2,FALSE()) -> 14 | N28: ATM-027 | O28: Самара, Куйбышева | P28: Model-Z | Q28: 46295.742 | R28: online | S28: 52
A29: T000028 | B29: ATM-002 | C29: 46267.863 | D29: снятие | E29: 1500 | F29: failed | G29: E03 | H29: =VLOOKUP(B29,$N$2:$S$41,3,FALSE()) -> Model-Y | I29: =VLOOKUP(B29,$N$2:$S$41,2,FALSE()) -> Москва, Арбат | J29: =IF(F29="success",1,0) -> 0 | K29: =VLOOKUP(H29,Lookup!$A$4:$B$6,2,FALSE()) -> 14 | N29: ATM-028 | O29: Самара, Молодогвардейская | P29: Model-X | Q29: 46295.949 | R29: online | S29: 33
A30: T000029 | B30: ATM-019 | C30: 46267.897 | D30: запрос баланса | E30: 0 | F30: success | H30: =VLOOKUP(B30,$N$2:$S$41,3,FALSE()) -> Model-X | I30: =VLOOKUP(B30,$N$2:$S$41,2,FALSE()) -> Новосибирск, Красный пр-т | J30: =IF(F30="success",1,0) -> 1 | K30: =VLOOKUP(H30,Lookup!$A$4:$B$6,2,FALSE()) -> 18 | N30: ATM-029 | O30: Ростов-на-Дону, Садовая | P30: Model-Y | Q30: 46295.333 | R30: maintenance | S30: 57
A31: T000030 | B31: ATM-008 | C31: 46267.922 | D31: снятие | E31: 15000 | F31: success | H31: =VLOOKUP(B31,$N$2:$S$41,3,FALSE()) -> Model-Y | I31: =VLOOKUP(B31,$N$2:$S$41,2,FALSE()) -> Санкт-Петербург, Московский пр-т | J31: =IF(F31="success",1,0) -> 1 | K31: =VLOOKUP(H31,Lookup!$A$4:$B$6,2,FALSE()) -> 14 | N31: ATM-030 | O31: Ростов-на-Дону, Будённовский | P31: Model-Z | Q31: 46295.793 | R31: online | S31: 38
A32: T000031 | B32: ATM-035 | C32: 46267.937 | D32: снятие | E32: 1500 | F32: success | H32: =VLOOKUP(B32,$N$2:$S$41,3,FALSE()) -> Model-Y | I32: =VLOOKUP(B32,$N$2:$S$41,2,FALSE()) -> Воронеж, Плехановская | J32: =IF(F32="success",1,0) -> 1 | K32: =VLOOKUP(H32,Lookup!$A$4:$B$6,2,FALSE()) -> 14 | N32: ATM-031 | O32: Ростов-на-Дону, Пушкинская | P32: Model-X | Q32: 46295.833 | R32: online | S32: 18
A33: T000032 | B33: ATM-013 | C33: 46267.94 | D33: внесение | E33: 3000 | F33: success | H33: =VLOOKUP(B33,$N$2:$S$41,3,FALSE()) -> Model-X | I33: =VLOOKUP(B33,$N$2:$S$41,2,FALSE()) -> Казань, Пушкина | J33: =IF(F33="success",1,0) -> 1 | K33: =VLOOKUP(H33,Lookup!$A$4:$B$6,2,FALSE()) -> 18 | N33: ATM-032 | O33: Краснодар, Красная | P33: Model-Y | Q33: 46295.728 | R33: online | S33: 63
A34: T000033 | B34: ATM-032 | C34: 46268.281 | D34: перевод | E34: 15000 | F34: success | H34: =VLOOKUP(B34,$N$2:$S$41,3,FALSE()) -> Model-Y | I34: =VLOOKUP(B34,$N$2:$S$41,2,FALSE()) -> Краснодар, Красная | J34: =IF(F34="success",1,0) -> 1 | K34: =VLOOKUP(H34,Lookup!$A$4:$B$6,2,FALSE()) -> 14 | N34: ATM-033 | O34: Краснодар, Северная | P34: Model-Z | Q34: 46292.281 | R34: offline | S34: 86
A35: T000034 | B35: ATM-001 | C35: 46268.369 | D35: снятие | E35: 2000 | F35: success | H35: =VLOOKUP(B35,$N$2:$S$41,3,FALSE()) -> Model-X | I35: =VLOOKUP(B35,$N$2:$S$41,2,FALSE()) -> Москва, Тверская | J35: =IF(F35="success",1,0) -> 1 | K35: =VLOOKUP(H35,Lookup!$A$4:$B$6,2,FALSE()) -> 18 | N35: ATM-034 | O35: Краснодар, Гимназическая | P35: Model-X | Q35: 46295.74 | R35: online | S35: 48
A36: T000035 | B36: ATM-029 | C36: 46268.454 | D36: снятие | E36: 5000 | F36: success | H36: =VLOOKUP(B36,$N$2:$S$41,3,FALSE()) -> Model-Y | I36: =VLOOKUP(B36,$N$2:$S$41,2,FALSE()) -> Ростов-на-Дону, Садовая | J36: =IF(F36="success",1,0) -> 1 | K36: =VLOOKUP(H36,Lookup!$A$4:$B$6,2,FALSE()) -> 14 | N36: ATM-035 | O36: Воронеж, Плехановская | P36: Model-Y | Q36: 46295.735 | R36: online
A37: T000036 | B37: ATM-006 | C37: 46268.5 | D37: перевод | E37: 7000 | F37: success | H37: =VLOOKUP(B37,$N$2:$S$41,3,FALSE()) -> Model-X | I37: =VLOOKUP(B37,$N$2:$S$41,2,FALSE()) -> Москва, Профсоюзная | J37: =IF(F37="success",1,0) -> 1 | K37: =VLOOKUP(H37,Lookup!$A$4:$B$6,2,FALSE()) -> 18 | N37: ATM-036 | O37: Воронеж, Кольцовская | P37: Model-X | Q37: 46295.85 | R37: online | S37: 62
A38: T000037 | B38: ATM-032 | C38: 46268.513 | D38: снятие | E38: 15000 | F38: success | H38: =VLOOKUP(B38,$N$2:$S$41,3,FALSE()) -> Model-Y | I38: =VLOOKUP(B38,$N$2:$S$41,2,FALSE()) -> Краснодар, Красная | J38: =IF(F38="success",1,0) -> 1 | K38: =VLOOKUP(H38,Lookup!$A$4:$B$6,2,FALSE()) -> 14 | N38: ATM-037 | O38: Воронеж, Революции | P38: Model-X | Q38: 46295.948 | R38: online | S38: 49
A39: T000038 | B39: ATM-008 | C39: 46268.589 | D39: снятие | E39: 10000 | F39: success | H39: =VLOOKUP(B39,$N$2:$S$41,3,FALSE()) -> Model-Y | I39: =VLOOKUP(B39,$N$2:$S$41,2,FALSE()) -> Санкт-Петербург, Московский пр-т | J39: =IF(F39="success",1,0) -> 1 | K39: =VLOOKUP(H39,Lookup!$A$4:$B$6,2,FALSE()) -> 14 | N39: ATM-038 | O39: Уфа, Ленина | P39: Model-Y | Q39: 46295.619 | R39: online | S39: 59
A40: T000040 | B40: ATM-009 | C40: 46268.755 | D40: запрос баланса | E40: 0 | F40: success | H40: =VLOOKUP(B40,$N$2:$S$41,3,FALSE()) -> Model-Z | I40: =VLOOKUP(B40,$N$2:$S$41,2,FALSE()) -> Санкт-Петербург, Лиговский пр-т | J40: =IF(F40="success",1,0) -> 1 | K40: =VLOOKUP(H40,Lookup!$A$4:$B$6,2,FALSE()) -> 16 | N40: ATM-039 | O40: Уфа, Чернышевского | P40: Model-Z | Q40: 46295.883 | R40: online | S40: 87
A41: T000041 | B41: ATM-011 | C41: 46268.774 | D41: внесение | E41: 1000 | F41: success | H41: =VLOOKUP(B41,$N$2:$S$41,3,FALSE()) -> Model-X | I41: =VLOOKUP(B41,$N$2:$S$41,2,FALSE()) -> Казань, Баумана | J41: =IF(F41="success",1,0) -> 1 | K41: =VLOOKUP(H41,Lookup!$A$4:$B$6,2,FALSE()) -> 18 | N41: ATM-040 | O41: Уфа, Мингажева | P41: Model-X | Q41: 46295.729 | R41: online | S41: 62
...

Sheet Pivot
A1: Сводка: model × location (формулы COUNTIFS/SUMIFS по листу Raw)
A2: Вычисляемое поле Success Rate в сводной таблице Excel не умеет считать «долю status = success» — поэтому в Raw добавлен столбец is_success (1/0), а Success Rate = SUM(is_success) / COUNT.
A4: model | B4: location | C4: txns | D4: sum_amount, ₽ | E4: success_txns | F4: success_rate
A5: Model-X | B5: Воронеж, Кольцовская | C5: =COUNTIFS(Raw!$H$2:$H$656,A5,Raw!$I$2:$I$656,B5) -> 17 | D5: =SUMIFS(Raw!$E$2:$E$656,Raw!$H$2:$H$656,A5,Raw!$I$2:$I$656,B5) -> 98500 | E5: =SUMIFS(Raw!$J$2:$J$656,Raw!$H$2:$H$656,A5,Raw!$I$2:$I$656,B5) -> 16 | F5: =IF(C5=0,"—",E5/C5) -> 0.94117647
A6: Model-X | B6: Воронеж, Революции | C6: =COUNTIFS(Raw!$H$2:$H$656,A6,Raw!$I$2:$I$656,B6) -> 19 | D6: =SUMIFS(Raw!$E$2:$E$656,Raw!$H$2:$H$656,A6,Raw!$I$2:$I$656,B6) -> 72000 | E6: =SUMIFS(Raw!$J$2:$J$656,Raw!$H$2:$H$656,A6,Raw!$I$2:$I$656,B6) -> 17 | F6: =IF(C6=0,"—",E6/C6) -> 0.89473684
A7: Model-X | B7: Екатеринбург, Малышева | C7: =COUNTIFS(Raw!$H$2:$H$656,A7,Raw!$I$2:$I$656,B7) -> 20 | D7: =SUMIFS(Raw!$E$2:$E$656,Raw!$H$2:$H$656,A7,Raw!$I$2:$I$656,B7) -> 103500 | E7: =SUMIFS(Raw!$J$2:$J$656,Raw!$H$2:$H$656,A7,Raw!$I$2:$I$656,B7) -> 15 | F7: =IF(C7=0,"—",E7/C7) -> 0.75
A8: Model-X | B8: Казань, Баумана | C8: =COUNTIFS(Raw!$H$2:$H$656,A8,Raw!$I$2:$I$656,B8) -> 18 | D8: =SUMIFS(Raw!$E$2:$E$656,Raw!$H$2:$H$656,A8,Raw!$I$2:$I$656,B8) -> 60500 | E8: =SUMIFS(Raw!$J$2:$J$656,Raw!$H$2:$H$656,A8,Raw!$I$2:$I$656,B8) -> 14 | F8: =IF(C8=0,"—",E8/C8) -> 0.77777778
A9: Model-X | B9: Казань, Пушкина | C9: =COUNTIFS(Raw!$H$2:$H$656,A9,Raw!$I$2:$I$656,B9) -> 19 | D9: =SUMIFS(Raw!$E$2:$E$656,Raw!$H$2:$H$656,A9,Raw!$I$2:$I$656,B9) -> 44500 | E9: =SUMIFS(Raw!$J$2:$J$656,Raw!$H$2:$H$656,A9,Raw!$I$2:$I$656,B9) -> 18 | F9: =IF(C9=0,"—",E9/C9) -> 0.94736842
A10: Model-X | B10: Краснодар, Гимназическая | C10: =COUNTIFS(Raw!$H$2:$H$656,A10,Raw!$I$2:$I$656,B10) -> 19 | D10: =SUMIFS(Raw!$E$2:$E$656,Raw!$H$2:$H$656,A10,Raw!$I$2:$I$656,B10) -> 109000 | E10: =SUMIFS(Raw!$J$2:$J$656,Raw!$H$2:$H$656,A10,Raw!$I$2:$I$656,B10) -> 17 | F10: =IF(C10=0,"—",E10/C10) -> 0.89473684
A11: Model-X | B11: Москва, Ленинградский пр-т | C11: =COUNTIFS(Raw!$H$2:$H$656,A11,Raw!$I$2:$I$656,B11) -> 24 | D11: =SUMIFS(Raw!$E$2:$E$656,Raw!$H$2:$H$656,A11,Raw!$I$2:$I$656,B11) -> 92000 | E11: =SUMIFS(Raw!$J$2:$J$656,Raw!$H$2:$H$656,A11,Raw!$I$2:$I$656,B11) -> 20 | F11: =IF(C11=0,"—",E11/C11) -> 0.83333333
A12: Model-X | B12: Москва, Профсоюзная | C12: =COUNTIFS(Raw!$H$2:$H$656,A12,Raw!$I$2:$I$656,B12) -> 19 | D12: =SUMIFS(Raw!$E$2:$E$656,Raw!$H$2:$H$656,A12,Raw!$I$2:$I$656,B12) -> 77500 | E12: =SUMIFS(Raw!$J$2:$J$656,Raw!$H$2:$H$656,A12,Raw!$I$2:$I$656,B12) -> 17 | F12: =IF(C12=0,"—",E12/C12) -> 0.89473684
A13: Model-X | B13: Москва, Тверская | C13: =COUNTIFS(Raw!$H$2:$H$656,A13,Raw!$I$2:$I$656,B13) -> 25 | D13: =SUMIFS(Raw!$E$2:$E$656,Raw!$H$2:$H$656,A13,Raw!$I$2:$I$656,B13) -> 146500 | E13: =SUMIFS(Raw!$J$2:$J$656,Raw!$H$2:$H$656,A13,Raw!$I$2:$I$656,B13) -> 21 | F13: =IF(C13=0,"—",E13/C13) -> 0.84
A14: Model-X | B14: Нижний Новгород, Белинского | C14: =COUNTIFS(Raw!$H$2:$H$656,A14,Raw!$I$2:$I$656,B14) -> 12 | D14: =SUMIFS(Raw!$E$2:$E$656,Raw!$H$2:$H$656,A14,Raw!$I$2:$I$656,B14) -> 38500 | E14: =SUMIFS(Raw!$J$2:$J$656,Raw!$H$2:$H$656,A14,Raw!$I$2:$I$656,B14) -> 10 | F14: =IF(C14=0,"—",E14/C14) -> 0.83333333
A15: Model-X | B15: Новосибирск, Гоголя | C15: =COUNTIFS(Raw!$H$2:$H$656,A15,Raw!$I$2:$I$656,B15) -> 24 | D15: =SUMIFS(Raw!$E$2:$E$656,Raw!$H$2:$H$656,A15,Raw!$I$2:$I$656,B15) -> 66500 | E15: =SUMIFS(Raw!$J$2:$J$656,Raw!$H$2:$H$656,A15,Raw!$I$2:$I$656,B15) -> 19 | F15: =IF(C15=0,"—",E15/C15) -> 0.79166667
A16: Model-X | B16: Новосибирск, Дуси Ковальчук | C16: =COUNTIFS(Raw!$H$2:$H$656,A16,Raw!$I$2:$I$656,B16) -> 13 | D16: =SUMIFS(Raw!$E$2:$E$656,Raw!$H$2:$H$656,A16,Raw!$I$2:$I$656,B16) -> 37000 | E16: =SUMIFS(Raw!$J$2:$J$656,Raw!$H$2:$H$656,A16,Raw!$I$2:$I$656,B16) -> 11 | F16: =IF(C16=0,"—",E16/C16) -> 0.84615385
... A44: Model-Z | B44: Уфа, Чернышевского | C44: =COUNTIFS(Raw!$H$2:$H$656,A44,Raw!$I$2:$I$656,B44) -> 0 | D44: =SUMIFS(Raw!$E$2:$E$656,Raw!$H$2:$H$656,A44,Raw!$I$2:$I$656,B44) -> 0 | E44: =SUMIFS(Raw!$J$2:$J$656,Raw!$H$2:$H$656,A44,Raw!$I$2:$I$656,B44) -> 0 | F44: =IF(C44=0,"—",E44/C44) -> —
A45: ИТОГО | C45: =SUM(C5:C44) -> 655 | D45: =SUM(D5:D44) -> 2722000 | E45: =SUM(E5:E44) -> 581 | F45: =E45/C45 -> 0.8870229

Sheet Lookup
A1: model_cost — стоимость обслуживания одной транзакции, ₽ (условные значения для учебного проекта)
A3: model | B3: cost_per_txn_rub | D3: model | E3: txns | F3: service_cost_rub (СУММЕСЛИ) | G3: success_rate
A4: Model-X | B4: 18 | D4: =A4 -> Model-X | E4: =COUNTIF(Raw!$H$2:$H$656,D4) -> 329 | F4: =SUMIF(Raw!$H$2:$H$656,D4,Raw!$K$2:$K$656) -> 5922 | G4: =SUMIFS(Raw!$J$2:$J$656,Raw!$H$2:$H$656,D4)/E4 -> 0.83586626
A5: Model-Y | B5: 14 | D5: =A5 -> Model-Y | E5: =COUNTIF(Raw!$H$2:$H$656,D5) -> 185 | F5: =SUMIF(Raw!$H$2:$H$656,D5,Raw!$K$2:$K$656) -> 2590 | G5: =SUMIFS(Raw!$J$2:$J$656,Raw!$H$2:$H$656,D5)/E5 -> 0.97297297
A6: Model-Z | B6: 16 | D6: =A6 -> Model-Z | E6: =COUNTIF(Raw!$H$2:$H$656,D6) -> 141 | F6: =SUMIF(Raw!$H$2:$H$656,D6,Raw!$K$2:$K$656) -> 2256 | G6: =SUMIFS(Raw!$J$2:$J$656,Raw!$H$2:$H$656,D6)/E6 -> 0.89361702
D7: ИТОГО | E7: =SUM(E4:E6) -> 655 | F7: =SUM(F4:F6) -> 10768 | G7: =SUM(Raw!$J$2:$J$656)/E7 -> 0.8870229
A9: Проверка: ИТОГО txns должно равняться числу строк Raw | D9: =IF(E7=COUNTA(Raw!$A$2:$A$656),"OK","ОШИБКА") -> OK
